Workbook
Name Амортизац: #REF!
Name Дата_первой_выплаты: #REF!
Name Кредит_Б__в_USD: #REF!
Name Курс_0198: '[1]Поток реальных денег'!#REF!
Name Курс_USD: #REF!
Name Льготный_период: #REF!
Name Местные_продажи: #REF!
Name Объем: #REF!
Name объем100: #REF!
Name П\роцентная_ставка: #REF!
Name процент_на_маркетинг: #REF!
Name Срок_пользования_кредитом: #REF!
Name ст.пр.: #REF!
Name ЦенаЗаЕд.: #REF!
Name ценмест: #REF!
Name ценэксп: #REF!
Name Экспорт: #REF!
Name Курс_USD: #REF!
Name Льготный_период: #REF!
Name Объем: #REF!
Name объем100: #REF!

Sheet ВВОД
B15: Loyiha nomi:
B16: Mebel ishlab chiqarish sexi
B17: Loyiha tashabbuskori:
B18: Orzu MCHJ
B19: Tadbirkor manzili:
B20: Toshkent sh., Yunusobod tumani
B21: Xizmat ko‘rsatuvchi bank:
B22: Hamkorbank ATB
B23: STIR:
B24: 123456789
B25: JSHSHIR:
B26: 12345678901234
... B87: 30
B90: 6858711.4
B91: 5.5947949e+08
B92: 2.0947949e+08

Sheet ProjCost
B2: LOYIHA QIYMATI | G2: 1-ILOVA
C3: % | D3: =+ВВОД!B23 | E3: BANK KREDITI, so'm | F3: Jami (so'm) | G3: Foiz hisobida
B4: Asosiy vositalarni sotib olish (mebel jihozlari) | D4: 0 | E4: =+ВВОД!B44 | F4: =E4+D4 | G4: =F4/$F$13
B5: Asosiy vositalar | D5: =+ВВОД!B42 | E5: 0 | F5: =D5 | G5: =F5/F13
B6: JAMI mablag'lar | D6: =+SUM(D4:D5) | E6: =SUM(E4:E4) | F6: =SUM(F4:F4)
B7: Aylanma kapital | D7: =SUM(D8:D8)+D9 | E7: 0 | F7: =SUM(C7:D7)
B8: Aylanma kapital | D8: ='Share of Costs'!G8 | E8: 0 | F8: =SUM(C8:D8) | G8: =F8/$F$13
B9: MOLIYAVIY XARAJATLAR | D9: ='Share of Costs'!G9 | F9: =SUM(D9:D9) | G9: =F9/$F$13
B10: MOLIYAVIY XARAJATLAR | D10: =SUM(D11:D12) | E10: =+E12 | F10: =SUM(F11:F12)
B11: Sug'urta | D11: ='Share of Costs'!C11 | E11: 0 | F11: =SUM(D11:D11) | G11: =F11/$F$13
B12: Kredit olish uchun boshqa xarajatlar | D12: ='Share of Costs'!C12 | E12: 0 | F12: =SUM(D12:D12) | G12: =F12/$F$13
B13: LOYIHA QIYMATI | D13: =D7+D6+D10 | E13: =+E4+E5 | F13: =E13+D13 | G13: =SUM(G4:G12)

Sheet FinPlan
B1: MOLIYAVIY REJA | G1: 2-ILOVA
D2: Milly valyuta, so'm | E2: Jami | F2: Struktura | G2: Foizda
B3: Kapital
B4: O'z mablag'lari | D4: ='Share of Costs'!C14 | E4: =SUM(D4:D4) | F4: =E4/E5
B5: Jami kapital | D5: =SUM(D3:D4) | E5: =SUM(E4:E4) | G5: =E5/E10
B6: Qarzga olingan mablag'lar
D7: =ProjCost!E6 | E7: =D7
B8: Jami qarz mablag'lari | D8: =SUM(D7:D7) | E8: =SUM(E7:E7) | G8: =E8/E10
B9: Jami moliyalashtirish | E9: =E10-ProjCost!F13
B10: Jami moliyalashtirish | D10: =D5+D8 | E10: =E5+E8 | G10: =G5+G8
E11: =TODAY()
C12: Финансирование от Стройкомплектсервис | D12: в долл.США | E12: Всего
B13: 1. | C13: Строительство и реконстр. сущ. здания | D13: 0 | E13: =D13+#REF!
B14: 2. | C14: Местное сырье | D14: 0 | E14: =D14+#REF!
B15: 3. | C15: Резерв на рабочий капитал | D15: 0 | E15: =D15+#REF!
C16: Всего от СКС | D16: =SUM(D13:D15) | E16: =D16+#REF!
B17: Разница будет оплачена посредством предоставления кредита на сумму | E17: =#REF!
B18: сроком на 1-год с начала производства
C20: Финансирование от АО "Подъемник" | D20: в твердой валюте | E20: Всего
B21: 1. | C21: Здания и сооружения и инфраструктура к ним | D21: 0 | E21: =SUM(D21:D21)
C22: Всего от Подъемник | D22: =SUM(D21:D21) | E22: =SUM(E21:E21)
C25: Финансирвание от МФК | D25: в твердой валюте | E25: Всего
B26: 1. | C26: Машины и оборудования | D26: =ProjCost!#REF! | E26: =D26+#REF!
B27: 2. | C27: Транспорт и страхование | D27: =ProjCost!#REF! | E27: =D27+#REF!
B28: 3. | C28: Монтаж и запуск | D28: =ProjCost!#REF! | E28: =D28+#REF!
B29: 4. | C29: Грузовая машина | D29: =ProjCost!#REF! | E29: =D29+#REF!
B30: 5. | C30: Охранная видео система | D30: =ProjCost!#REF! | E30: =D30+#REF!
B31: 6. | C31: Накладные расходы | D31: =ProjCost!#REF! | E31: =D31+#REF!
B32: 7. | C32: Вспомогательные материалы | D32: =ProjCost!#REF! | E32: =D32+#REF!
B33: 8. | C33: Запасные части | D33: =ProjCost!#REF! | E33: =D33+#REF!
B34: 9. | C34: Финансовые расходы | D34: =ProjCost!#REF!+ProjCost!#REF!+ProjCost!#REF!+ProjCost!#REF! | E34: =D34+#REF!
B35: 10. | C35: Резерв | D35: =ProjCost!#REF! | E35: =D35+#REF!
C36: Всего от МФК | D36: =SUM(D26:D35) | E36: =D36+#REF!
C38: Финансирование от Банка "Асака" (по кредитной линии МФК/Асака) | D38: в твердой валюте | E38: Всего
B39: 1. | C39: Машины и оборудования | D39: =ProjCost!#REF! | E39: =D39+#REF!
C40: Всего от Банка "Асака" | D40: =D39 | E40: =D40+#REF!
C42: Недостающая сумма | D42: в твердой валюте | E42: Всего
B43: 1. | C43: Проценты в инв. Период | D43: =ProjCost!#REF! | E43: =SUM(D43:D43)
B44: 2. | C44: Страхование залога | D44: 0 | E44: =SUM(D44:D44)
B45: 3. | C45: оформление залога | D45: 0 | E45: =SUM(D45:D45)
...

Sheet Share of Costs
B2: LOYIHA ISHTIROKCHILARI XARAJATLARINING ulushi | G2: 3-ILOVA
B3: Ko'rsatkichlar | C3: O'z mablag'lari | D3: Milliy valyutada, so'm | E3: Jami, summa | F3: =ProjCost!E3 | G3: Jami, summa
B4: =ProjCost!B4 | C4: 0 | E4: 0 | F4: =ProjCost!E4 | G4: =F4
B5: Asosiy vositalar | C5: =ProjCost!D5 | F5: 0 | G5: =C5
B6: ASOSIY KAPITALLARNING TO'LIQ XARAJATLARI | C6: =C4+C5 | E6: =#REF!+#REF!+E4 | F6: =F4 | G6: =G4+G5
B7: Aylanma kapital | C7: =C8+C9 | E7: =E8+E9 | F7: 0 | G7: =G8+G9
B8: Aylanma kapital | C8: 0 | E8: 0 | F8: 0 | G8: =C8+E8
B10: MOLIYAVIY XARAJATLAR | C10: =SUM(C11:C12) | E10: =SUM(E12:E12) | F10: 0 | G10: =E10+C10
B11: Sug'urta | C11: 0 | E11: 0 | F11: 0 | G11: =C11+E11
B12: Kredit olish uchun boshqa xarajatlar | C12: =(F13+F14)*1% | E12: 0 | F12: 0 | G12: =C12+E12
B13: TO'LIQ ISHLAB CHIQARISH XARAJATLARI | C13: =C7+C6+C10 | E13: =E6+E7 | F13: =+F6 | G13: =G7+G6+G10
B14: JAMI BIRINCHI INVESTITSIYA XARAJATLARI | C14: =C13 | E14: =E13 | F14: =F13 | G14: =G13

Sheet Depreciate
I2: 4-ILOVA
B3: AMORTIZATSIYA HISOBOTLARI
B4: Amortizatsiya ob'ektlari | C4: Xarajat (amortizatsiya qilinadigan baza) | D4: Amortizatsiya darajasi (%) | E4: 1-yil | F4: 2-yil | G4: 3-yil | H4: 4-yil | I4: 5-yil | J4: 6-yil | K4: 7-yil
B5: ='Share of Costs'!B5 | C5: =+'Share of Costs'!G14 | D5: 0.15 | E5: 75000000 | F5: 75000000 | G5: 75000000 | H5: 75000000 | I5: 75000000 | J5: 75000000 | K5: 50000000
B6: ='Share of Costs'!#REF! | C6: ='Share of Costs'!#REF! | D6: 0.15 | E6: =C6*D6 | F6: =E6 | G6: =F6 | H6: =G6 | I6: =H6 | J6: =I6 | K6: =J6
B7: Jami amortizatsiya | C7: Х | D7: Х | E7: 75000000 | F7: 75000000 | G7: 75000000 | H7: 75000000 | I7: 75000000 | J7: 75000000 | K7: 50000000
B8: Yig'ilgan amortizatsiya | C8: Х | D8: Х | E8: 75000000 | F8: 150000000 | G8: 225000000 | H8: 300000000 | I8: 375000000 | J8: 450000000 | K8: 350000000

Sheet Labour
F2: 5-ILOVA
B3: ISH HAQI XARAJATLARI
B4: LAVOZIM | C4: SONI | D4: MAOSH (so'm) | E4: Oylik maosh (so'm) | F4: YILLIK maosh (so'm)
B5: Ma'muriyat
B6: Direktor | C6: =+ВВОД!B65 | D6: =+ВВОД!B74 | E6: =C6*D6 | F6: =E6*12
B7: JAMI | C7: =+C6 | E7: =SUM(E6:E6) | F7: =SUM(F6:F6)
B8: Ijtimoiy soliq | C8: 0.12 | D8: yillik ish haqi fondidan | F8: =F7*C8
B9: JAMI | C9: =+C6 | F9: =F7+F8
B11: ISHCHI XODIM | C11: SONI | D11: MAOSH (so'm) | E11: Oylik maosh (so'm) | F11: YILLIK maosh (so'm)
B12: Ishchilar | C12: =+ВВОД!B67 | D12: =+ВВОД!B72 | E12: =+C12*D12 | F12: =+E12*12
B13: JAMI | C13: =+C12 | E13: 3600000 | F13: =SUM(F12)
B14: Ijtimoiy soliq | C14: 0.12 | D14: yillik ish haqi fondidan | F14: =+F13*C14
B15: JAMI | C15: =+C12 | F15: =+F13+F14
B16: YANGI IShChI XODIM
B17: Ishchi | C17: =+ВВОД!B69 | D17: =+ВВОД!B76 | E17: =+C17*D17 | F17: =+E17*12
B18: JAMI | C18: =+C17 | E18: =SUM(E17) | F18: =SUM(F17)
B19: Ijtimoiy soliq | C19: 0.12 | D19: yillik ish haqi fondidan | F19: =+F18*12%
B20: JAMI | C20: =+C17 | F20: =+F18+F19
B21: JAMI | C21: =+C9+C13+C18 | F21: =+F9+F15+F20
B23: FOYDALANISH XARAJATLARI
B25: BO'LIMLAR | C25: O'Lchov birligi | D25: YILLIK ISTE'MOL | E25: BIR BIRLIK NARXI (SO'M) | F25: YILLIK XARAJATLAR (SO'M)
B26: Elektr | C26: kvt/soat | D26: =+ВВОД!B81 | E26: 900 | F26: =D26*E26
B27: Gaz | C27: kb/m | D27: =+ВВОД!B83 | E27: 1000 | F27: =D27*E27
B28: Suv | C28: kb/m | D28: =+ВВОД!B85 | E28: 4800 | F28: =D28*E28
B29: Oqava suv | C29: kb/m | D29: =+ВВОД!B87 | E29: 1500 | F29: =D29*E29
B33: JAMI | C33: х | D33: х | E33: х | F33: =SUM(F26:F32)

Sheet ProdPlan
B2: Yotoq mebeli | G2: 6-ILOVA
B3: NOMI | C3: Ishlab chiqarish hajmi dona/yil | D3: Xizmat ko'rsatish soni | E3: Jami xizmat ko'rsatish hajmi dona/yil | F3: O'rtacha sotuv narxi (so'm) | G3: 1 yillik savdo tushumi
B4: =+ВВОД!B56 | C4: =+ВВОД!B58 | D4: =+ВВОД!B60 | E4: =C4*D4 | F4: =+ВВОД!B62 | G4: =E4*F4
B13: SOTISH REJASI
B14: NOMI | C14: Birlik | D14: SOTISH HAJMI MAX. PROD. YILGA DASTUR, BIRLIKLAR | F14: O'rtacha xizmat narxi (so'm) | G14: Zaxiradagi tayyor mahsulot
B15: =+B4 | C15: dona | D15: =E4 | F15: =F4 | G15: 0
B16: Parrandachilik | C16: шт | D16: =E6*12 | F16: =F6 | G16: 0
B17: =B7 | C17: шт | D17: =E7*12 | F17: =F7 | G17: 0
B18: "Bobur Аkbarov" MCHJ | C18: шт | D18: =E8*12 | F18: =F8 | G18: 0
B19: =B9 | C19: шт | D19: =E9*12 | F19: =F9 | G19: 0
B23: KO'RSATGICHLAR | C23: =Depreciate!E4 | D23: =Depreciate!F4 | E23: =Depreciate!G4 | F23: =Depreciate!H4 | G23: =Depreciate!I4 | H23: =Depreciate!J4 | I23: =Depreciate!K4
B24: Quvvatlarni ishga tushirish | C24: 0.7 | D24: 0.75 | E24: 0.8 | F24: 0.85 | G24: 0.9 | H24: 0.95 | I24: 1
B25: ISHLAB CHIQARISH HAJMI
B26: 30707942190044 | C26: =$D15*C$24 | D26: =$D15*D$24 | E26: =$D15*E$24 | F26: =$D15*F$24 | G26: =$D15*G$24 | H26: =$D15*H$24 | I26: =$D15*I$24
B27: =B16 | C27: =$D$16*C24 | D27: =$D$16*D24 | E27: =$D$16*E24 | F27: =$D$16*F24 | G27: =$D$16*G24 | H27: =$D$16*H24 | I27: =$D$16*I24
B28: Tovuq boqish | C28: =$D$17*C24 | D28: =$D$17*D24 | E28: =$D$17*E24 | F28: =$D$17*F24 | G28: =$D$17*G24 | H28: =$D$17*H24 | I28: =$D$17*I24
B29: =B18 | C29: =$D$18*C24 | D29: =$D$18*D24 | E29: =$D$18*E24 | F29: =$D$18*F24 | G29: =$D$18*G24 | H29: =$D$18*H24 | I29: =$D$18*I24
B30: Masuliyati cheklangan jamiyat | C30: =$D$19*C24 | D30: =$D$19*D24 | E30: =$D$19*E24 | F30: =$D$19*F24 | G30: =$D$19*G24 | H30: =$D$19*H24 | I30: =$D$19*I24
B31: =B20 | C31: =$D$20*C24 | D31: =$D$20*D24 | E31: =$D$20*E24 | F31: =$D$20*F24 | G31: =$D$20*G24 | H31: =$D$20*H24 | I31: =$D$20*I24
B32: Akbarov boburjon Sobirjon o'g'li
B33: ЗАПАСЫ НА КОНЕЦ ГОДА
B34: AD 3859855 | C34: =C26*G15 | D34: =D26*$G$15 | E34: =E26*$G$15 | F34: =F26*$G$15 | G34: =G26*$G$15 | H34: =H26*$G$15 | I34: =I26*$G$15
B35: =#REF! | C35: =#REF!*#REF! | D35: =#REF!*$G$15 | E35: =#REF!*$G$15 | F35: =#REF!*$G$15 | G35: =#REF!*$G$15 | H35: =#REF!*$G$15 | I35: =#REF!*$G$15
B36: 07.07.1994 | C36: =C27*$G16 | D36: =D27*$G16 | E36: =E27*$G16 | F36: =F27*$G16 | G36: =G27*$G16 | H36: =H27*$G16 | I36: =I27*$G16
B37: =B28 | C37: =C28*$G17 | D37: =D28*$G17 | E37: =E28*$G17 | F37: =F28*$G17 | G37: =G28*$G17 | H37: =H28*$G17 | I37: =I28*$G17
B38: 150000000 | C38: =C29*$G18 | D38: =D29*$G18 | E38: =E29*$G18 | F38: =F29*$G18 | G38: =G29*$G18 | H38: =H29*$G18 | I38: =I29*$G18
B39: =B30 | C39: =C30*$G19 | D39: =D30*$G19 | E39: =E30*$G19 | F39: =F30*$G19 | G39: =G30*$G19 | H39: =H30*$G19 | I39: =I30*$G19
B40: =B31 | C40: =C31*$G20 | D40: =D31*$G20 | E40: =E31*$G20 | F40: =F31*$G20 | G40: =G31*$G20 | H40: =H31*$G20 | I40: =I31*$G20
B42: 50000000
B43: =+B15 | C43: =C24*$E$4 | D43: =D24*$E$4 | E43: =E24*$E$4 | F43: =F24*$E$4 | G43: =G24*$E$4 | H43: =H24*$E$4 | I43: =I24*$E$4
B44: 100000000 | C44: =C27-C36 | D44: =D27-D36 | E44: =E27-E36 | F44: =F27-F36 | G44: =G27-G36 | H44: =H27-H36 | I44: =I27-I36
B45: =B37 | C45: =C28-C37 | D45: =D28-D37 | E45: =E28-E37 | F45: =F28-F37 | G45: =G28-G37 | H45: =H28-H37 | I45: =I28-I37
B46: 84 | C46: =C29-C38 | D46: =D29-D38 | E46: =E29-E38 | F46: =F29-F38 | G46: =G29-G38 | H46: =H29-H38 | I46: =I29-I38
B47: =B39 | C47: =C30-C39 | D47: =D30-D39 | E47: =E30-E39 | F47: =F30-F39 | G47: =G30-G39 | H47: =H30-H39 | I47: =I30-I39
B48: 24 | C48: =C31-C40 | D48: =D31-D40 | E48: =E31-E40 | F48: =F31-F40 | G48: =G31-G40 | H48: =H31-H40 | I48: =I31-I40
B50: 14
B51: =B43 | C51: =C43*$F15 | D51: =D43*$F15 | E51: =E43*$F15 | F51: =F43*$F15 | G51: =G43*$F15 | H51: =H43*$F15 | I51: =I43*$F15
B52: 1874001.2 | C52: =C44*$F16 | D52: =D44*$F16 | E52: =E44*$F16 | F52: =F44*$F16 | G52: =G44*$F16 | H52: =H44*$F16 | I52: =I44*$F16
B53: 1.574161e+08 | C53: =C45*$F17 | D53: =D45*$F17 | E53: =E45*$F17 | F53: =F45*$F17 | G53: =G45*$F17 | H53: =H45*$F17 | I53: =I45*$F17
B54: 57416097 | C54: =C46*$F18 | D54: =D46*$F18 | E54: =E46*$F18 | F54: =F46*$F18 | G54: =G46*$F18 | H54: =H46*$F18 | I54: =I46*$F18
...

Sheet Loans
F1: 8-9-ILOVA
B2: TO'LOV GRAFIGI
C3: Kredit muddati | D3: 84 | E3: oy
C5: Imtiyozli davr | D5: 6 | E5: oy
C6: Foiz | D6: 0.14 | E6: foiz
C7: Jamg'arma kompensatsiyasi | D7: 0 | E7: foiz
C9: Kredit summasi | D9: 350000000 | E9: so'm
B11: OYLAR | C11: ASOSIY QARZ TO'LOVI | D11: ASOSIY QARZ QOLDIG'I | E11: FOIZ TO'LOVLARI | F11: JAMI TO'LOV | G11: YIL
B12: 1 | C12: 0 | D12: 350000000 | E12: 4083333.3 | F12: 4083333.3 | G12: 1-yil
B13: 2 | C13: 0 | D13: 350000000 | E13: 4083333.3 | F13: 4083333.3 | G13: 1-yil
B14: 3 | C14: 0 | D14: 350000000 | E14: 4083333.3 | F14: 4083333.3 | G14: 1-yil
B15: 4 | C15: 0 | D15: 350000000 | E15: 4083333.3 | F15: 4083333.3 | G15: 1-yil
B16: 5 | C16: 0 | D16: 350000000 | E16: 4083333.3 | F16: 4083333.3 | G16: 1-yil
B17: 6 | C17: 0 | D17: 350000000 | E17: 4083333.3 | F17: 4083333.3 | G17: 1-yil
B18: 7 | C18: 2775378.1 | D18: 3.4722462e+08 | E18: 4083333.3 | F18: 6858711.4 | G18: 1-yil
B19: 8 | C19: 2807757.5 | D19: 3.4441686e+08 | E19: 4050953.9 | F19: 6858711.4 | G19: 1-yil
B20: 9 | C20: 2840514.7 | D20: 3.4157635e+08 | E20: 4018196.8 | F20: 6858711.4 | G20: 1-yil
B21: 10 | C21: 2873654 | D21: 3.387027e+08 | E21: 3985057.4 | F21: 6858711.4 | G21: 1-yil
B22: 11 | C22: 2907180 | D22: 3.3579552e+08 | E22: 3951531.5 | F22: 6858711.4 | G22: 1-yil
B23: 12 | C23: 2941097.1 | D23: 3.3285442e+08 | E23: 3917614.4 | F23: 6858711.4 | G23: 1-yil
... B95: 84 | C95: 6779615.9 | D95: 0 | E95: 79095.52 | F95: 6858711.4 | G95: 7-yil
B96: JAMI | D96: 350000000 | E96: 0 | F96: 2.0947949e+08 | G96: 5.5947949e+08

Sheet Taxes
G1: 7-ILOVA
B2: SOLIQ VA BOJLAR
B3: Soliqlar va chegirmalar turlari | C3: Soliq stavkasi | D3: Soliq solish obyekti | E3: =Depreciate!E4 | F3: =Depreciate!F4 | G3: =Depreciate!G4 | H3: =Depreciate!H4 | I3: =ProdPlan!G23 | J3: =ProdPlan!H23 | K3: =ProdPlan!I23
B4: Налог на имущество | C4: 0.035 | D4: от среднегодовой стоимости имущества | E4: 50400000 | F4: 54000000 | G4: 57600000 | H4: 61200000 | I4: 64800000 | J4: 68400000 | K4: 72000000
B6: Земельный налог | D6: исходя из занимаемой площади | E6: х | F6: 0 | G6: 0 | H6: 0 | I6: 0 | J6: 0 | K6: 0
B7: Налог на недра
B8: Налоги включаемые в себестоимость | E8: 50400000 | F8: 54000000 | G8: 57600000 | H8: 61200000 | I8: 64800000 | J8: 68400000 | K8: 72000000
B9: Отчисления в ЕДФ | C9: 0.01 | D9: от объема реализации
B10: Отчисления в пенс. Фонд | C10: 0.007 | D10: от объема реализации
B11: Экологический налог | C11: 0.01 | D11: от себестоимости | E11: 0 | F11: 0 | G11: 0
B12: Налоги и сборы вкл. в расходы периода
B13: Yagona soliq to'lovi | C13: 0.04 | D13: sotishdan tushgan daromad | E13: =4%*ProfLoss!C6 | F13: =4%*ProfLoss!D6 | G13: =4%*ProfLoss!E6 | H13: =4%*ProfLoss!F6 | I13: =4%*ProfLoss!G6 | J13: =4%*ProfLoss!H6 | K13: =4%*ProfLoss!I6
B14: Акцизный налог | C14: х | D14: от выручки | E14: 0 | F14: 0 | G14: 0 | H14: 0 | I14: 0 | J14: 0 | K14: 0
B15: НДС | C15: 0.2 | D15: от выручки | E15: 0 | F15: 0 | G15: 0 | H15: 0 | I15: 0 | J15: 0 | K15: 0
B16: Другие местные налоги и сборы | C16: 0.08 | D16: от прибыли | E16: 0 | F16: 0 | G16: 0 | H16: 0 | I16: 0 | J16: 0 | K16: 0
B17: JAMIY SOLIQ VA BOJLARI | E17: =E8+E13 | F17: =F8+F13 | G17: =G8+G13 | H17: =H8+H13 | I17: =I8+I13 | J17: =J8+J13 | K17: =K8+K13

Sheet Loans 2
F1: ПРИЛОЖЕНИЕ 9
B2: ВЫПЛАТЫ ПО ДОЛГОСРОЧНОМУ КРЕДИТУ
C3: Срок кредита | D3: 7 лет
C4: Инвестиционный период | D4: 0 месяц
C5: Льготный период | D5: 24 месяц
C6: Процентная ставка | D6: 0.055
C7: Периодичность выплат | D7: ежемесячно
C8: сумма кредита (евро) | D8: ='Share of Costs'!F6
B10: ПЕРИОДЫ ВЫПЛАТ | C10: ПОГАШЕНИЕ ОСНОВНОГО ДОЛГА | D10: ОСТАТОК ССУДНОЙ ЗАДОЛЖЕННОСТИ | E10: ВЫПЛАТЫ ПРОЦЕНТОВ | F10: ВСЕГО ВЫПЛАТ
B11: 1 мес | C11: 0 | D11: =D8 | E11: 0 | F11: =C11+E11 | G11: 1год
B12: 2 мес | C12: 0 | D12: =+D11-C11 | E12: 0 | F12: =C12+E12 | G12: 1год
B13: 3 мес | C13: 0 | D13: =+D12-C12 | E13: 0 | F13: =C13+E13 | G13: 1год
B14: 4 мес | C14: 0 | D14: =+D13-C13 | E14: 0 | F14: =C14+E14 | G14: 1год
B15: 5 мес | C15: 0 | D15: =+D14-C14 | E15: 0 | F15: =C15+E15 | G15: 1год
B16: 6 мес | C16: 0 | D16: =+D15-C15 | E16: =(D16*$D$6/2) | F16: =C16+E16 | G16: 1год
B17: 7 мес | C17: 0 | D17: =+D16-C16 | E17: 0 | F17: =C17+E17 | G17: 1год
B18: 8 мес | C18: 0 | D18: =+D17-C17 | E18: 0 | F18: =C18+E18 | G18: 1год
B19: 9 мес | C19: 0 | D19: =+D18-C18 | E19: 0 | F19: =C19+E19 | G19: 1год
B20: 10 мес | C20: 0 | D20: =+D19-C19 | E20: 0 | F20: =C20+E20 | G20: 1год
B21: 11 мес | C21: =C20 | D21: =+D20-C20 | E21: 0 | F21: =C21+E21 | G21: 1год
B22: 12 мес | C22: =C21 | D22: =+D21-C21 | E22: =(D22*$D$6/2) | F22: =C22+E22 | G22: 1год
B23: 13 мес | C23: =C22 | D23: =+D22-C22 | E23: 0 | F23: =C23+E23 | G23: 2год
B24: 14 мес | C24: =C23 | D24: =+D23-C23 | E24: 0 | F24: =C24+E24 | G24: 2год
B25: 15 мес | C25: =C24 | D25: =+D24-C24 | E25: 0 | F25: =C25+E25 | G25: 2год
B26: 16 мес | C26: =C25 | D26: =+D25-C25 | E26: 0 | F26: =C26+E26 | G26: 2год
B27: 17 мес | C27: =C26 | D27: =+D26-C26 | E27: 0 | F27: =C27+E27 | G27: 2год
B28: 18 мес | C28: =C27 | D28: =+D27-C27 | E28: =(D28*$D$6/2) | F28: =C28+E28 | G28: 2год
B29: 19 мес | C29: =C28 | D29: =+D28-C28 | E29: 0 | F29: =C29+E29 | G29: 2год
B30: 20 мес | C30: =C29 | D30: =+D29-C29 | E30: 0 | F30: =C30+E30 | G30: 2год
B31: 21 мес | C31: =C30 | D31: =+D30-C30 | E31: 0 | F31: =C31+E31 | G31: 2год
B32: 22 мес | C32: =C31 | D32: =+D31-C31 | E32: 0 | F32: =C32+E32 | G32: 2год
B33: 23 мес | C33: =C32 | D33: =+D32-C32 | E33: 0 | F33: =C33+E33 | G33: 2год
B34: 24 мес | C34: =D8/11 | D34: =+D33-C33 | E34: =(D34*$D$6/2) | F34: =C34+E34 | G34: 2год
B35: 25 мес | C35: 0 | D35: =+D34-C34 | E35: 0 | F35: =C35+E35 | G35: 3год
B36: 26 мес | C36: =C35 | D36: =+D35-C35 | E36: 0 | F36: =C36+E36 | G36: 3год
B37: 27 мес | C37: =C36 | D37: =+D36-C36 | E37: 0 | F37: =C37+E37 | G37: 3год
B38: 28 мес | C38: =C37 | D38: =+D37-C37 | E38: 0 | F38: =C38+E38 | G38: 3год
B39: 29 мес | C39: =C38 | D39: =+D38-C38 | E39: 0 | F39: =C39+E39 | G39: 3год
B40: 30 мес | C40: =C34 | D40: =+D39-C39 | E40: =(D40*$D$6/2) | F40: =C40+E40 | G40: 3год
B41: 31 мес | C41: 0 | D41: =+D40-C40 | E41: 0 | F41: =C41+E41 | G41: 3год
...

Sheet CostTotal
B2: TO'LIQ QUVVATLI BO'LGAN ISHLAB CHIQARISH XARAJATLARI | F2: 10-ILOVA | I2: Допущения использованные в расчетах
B3: XARAJATLAR | C3: TO'LIQ XARAJATLAR | D3: DOIMIY XARAJATLAR | F3: O'ZGARUVChAN XARAJATLAR | I3: Статьи расходов | J3: Примечания | K3: сумма в сум
D4: сумма | E4: % | F4: сумма | G4: % | I4: Расходы на рекламу | J4: 11200 тыс. сум в году, взята с предоставленного допольнения | K4: 80000
B5: To'g'ridan-to'g'ri xarajatlar | C5: =ProdPlan!G4*1% | D5: =C5*E5 | E5: 0.8 | F5: =+C5*G5 | G5: =1-E5 | I5: Торговые издержки | J5: Расходы на упаковку, невозврат. Тара и доставку, взят с доп. | K5: 80000
B7: Operatsion xarajatlar | C7: =Labour!F33 | D7: =C7*E7 | E7: 0.7 | F7: =+C7*G7 | G7: =1-E7 | I7: Инженерные коммуникации | J7: Прокладка, обсл. И прозвонка действующих инж. Комм. | K7: 2040
B8: Jami amortizatsiya | C8: =Depreciate!E7 | D8: =C8*E8 | E8: 1 | F8: =+C8*G8 | G8: =1-E8 | I8: Офисные расходы | J8: На покупку канц. Товаров и представительские расходы | K8: 10000
B9: Ishlab chiqarish xodimlarining ish haqi | C9: =Labour!F18+Labour!F13 | D9: =C9*E9 | E9: 0 | F9: =+C9*G9 | G9: =1-E9
B10: Ijtimoiy soliq | C10: =Labour!F19+Labour!F14 | D10: =C10*E10 | E10: 0 | F10: =+C10*G10 | G10: =1-E10 | I10: Транспортные расходы | J10: Расходы на ж/д транспорт | K10: 31360
B11: Ma'muriyat xodimlari ish haqi | C11: =Labour!F7 | D11: =C11*E11 | E11: 1 | F11: =+C11*G11 | G11: =1-E11 | I11: ГСМ | J11: На диз. Топливо 17 000 литров и автомобильных масел | K11: 7500
B12: =B10 | C12: =Labour!F8 | D12: =C12*E12 | E12: 1 | F12: =+C12*G12 | G12: =1-E12 | I12: Юридические и финансовые расходы | J12: На оплату банковских и юридических услуг | K12: 6000
B13: Boshqa ma'muriy xarajatlar | C13: =F18*0.2% | D13: =C13*E13 | E13: 0.5 | F13: =+C13*G13 | G13: =1-E13
B14: Asosiy vositalarga texnik xizmat ko'rsatish va joriy ta'mirlash | C14: =C8*1% | D14: =C14*E14 | E14: 0.7 | F14: =+C14*G14 | G14: =1-E14
B15: Marketing xarajatlari (0,2%) | C15: =F18*0.2% | D15: =C15*E15 | E15: 0.7 | F15: =+C15*G15 | G15: =1-E15
B16: Boshqa ko'zda tutilmagan xarajatlar | C16: =F18*0.2% | D16: =C16*E16 | E16: 0.5 | F16: =+C16*G16 | G16: =1-E16
B17: JAMI XARAJATLAR | C17: =SUM(C5:C16) | D17: =SUM(D5:D16) | E17: =D17/C17 | F17: =SUM(F5:F16) | G17: =F17/C17
B18: TO'LIQ QUVVATDA SOTISH | F18: =ProdPlan!D15*ProdPlan!F15+ProdPlan!D16*ProdPlan!F16+ProdPlan!D17*ProdPlan!F17+ProdPlan!D18*ProdPlan!F18+ProdPlan!D19*ProdPlan!F19+ProdPlan!D20*ProdPlan!F20 | I18: Итого прочие расходы | K18: =SUM(K4:K15)
B19: ZARARSIZLANISH NUQTASI | F19: =D17/(F18-F17)

Sheet CostSold
B2: TO'LIQ YILLIK XARAJATLAR | G2: 11-ILOVA
B3: Xarajat moddalari | C3: =ProdPlan!C23 | D3: =ProdPlan!D23 | E3: =ProdPlan!E23 | F3: =ProdPlan!F23 | G3: =ProdPlan!G23 | H3: =ProdPlan!H23 | I3: =ProdPlan!I23
B4: Rivojlanish quvvati | C4: =ProdPlan!C24 | D4: =ProdPlan!D24 | E4: =ProdPlan!E24 | F4: =ProdPlan!F24 | G4: =ProdPlan!G24 | H4: =ProdPlan!H24 | I4: =ProdPlan!I24
B5: =CostTotal!B5 | C5: =CostTotal!$D$5+CostTotal!$F$5*C4 | D5: =CostTotal!$D$5+CostTotal!$F$5*D4 | E5: =CostTotal!$D$5+CostTotal!$F$5*E4 | F5: =CostTotal!$D$5+CostTotal!$F$5*F4 | G5: =CostTotal!$D$5+CostTotal!$F$5*G4 | H5: =CostTotal!$D$5+CostTotal!$F$5*H4 | I5: =CostTotal!$D$5+CostTotal!$F$5*I4
B6: =+CostTotal!B9 | C6: =CostTotal!$D$9+CostTotal!$F$9*CostSold!C4 | D6: =CostTotal!$D$9+CostTotal!$F$9*CostSold!D4 | E6: =CostTotal!$D$9+CostTotal!$F$9*CostSold!E4 | F6: =CostTotal!$D$9+CostTotal!$F$9*CostSold!F4 | G6: =CostTotal!$D$9+CostTotal!$F$9*CostSold!G4 | H6: =CostTotal!$D$9+CostTotal!$F$9*CostSold!H4 | I6: =CostTotal!$D$9+CostTotal!$F$9*CostSold!I4
B7: =+CostTotal!B10 | C7: =CostTotal!$D$10+CostTotal!$F$10*CostSold!C4 | D7: =(CostTotal!$D$10+CostTotal!$F$10*CostSold!D4) | E7: =(CostTotal!$D$10+CostTotal!$F$10*CostSold!E4) | F7: =(CostTotal!$D$10+CostTotal!$F$10*CostSold!F4) | G7: =(CostTotal!$D$10+CostTotal!$F$10*CostSold!G4) | H7: =(CostTotal!$D$10+CostTotal!$F$10*CostSold!H4) | I7: =(CostTotal!$D$10+CostTotal!$F$10*CostSold!I4)
B8: =CostTotal!B7 | C8: =CostTotal!$D$7+CostTotal!$F$7*CostSold!C4 | D8: =CostTotal!$D$7+CostTotal!$F$7*CostSold!D4 | E8: =CostTotal!$D$7+CostTotal!$F$7*CostSold!E4 | F8: =CostTotal!$D$7+CostTotal!$F$7*CostSold!F4 | G8: =CostTotal!$D$7+CostTotal!$F$7*CostSold!G4 | H8: =CostTotal!$D$7+CostTotal!$F$7*CostSold!H4 | I8: =CostTotal!$D$7+CostTotal!$F$7*CostSold!I4
B9: Amortizatsiya | C9: =Depreciate!E7 | D9: =Depreciate!F7 | E9: =Depreciate!G7 | F9: =Depreciate!H7 | G9: =Depreciate!I7 | H9: =Depreciate!J7 | I9: =Depreciate!K7
B10: TANNARX | C10: =+C9+C8+C7+C6+C5 | D10: =+D9+D8+D7+D6+D5 | E10: =+E9+E8+E7+E6+E5 | F10: =+F9+F8+F7+F6+F5 | G10: =+G9+G8+G7+G6+G5 | H10: =+H9+H8+H7+H6+H5 | I10: =+I9+I8+I7+I6+I5
B11: =CostTotal!B11 | C11: =+CostTotal!$D$11+CostTotal!$F$11*CostSold!C4 | D11: =+CostTotal!$D$11+CostTotal!$F$11*CostSold!D4 | E11: =+CostTotal!$D$11+CostTotal!$F$11*CostSold!E4 | F11: =+CostTotal!$D$11+CostTotal!$F$11*CostSold!F4 | G11: =+CostTotal!$D$11+CostTotal!$F$11*CostSold!G4 | H11: =+CostTotal!$D$11+CostTotal!$F$11*CostSold!H4 | I11: =+CostTotal!$D$11+CostTotal!$F$11*CostSold!I4
B12: =+B7 | C12: =+CostTotal!$D$12+CostTotal!$F$12*CostSold!C4 | D12: =+CostTotal!$D$12+CostTotal!$F$12*CostSold!D4 | E12: =+CostTotal!$D$12+CostTotal!$F$12*CostSold!E4 | F12: =+CostTotal!$D$12+CostTotal!$F$12*CostSold!F4 | G12: =+CostTotal!$D$12+CostTotal!$F$12*CostSold!G4 | H12: =+CostTotal!$D$12+CostTotal!$F$12*CostSold!H4 | I12: =+CostTotal!$D$12+CostTotal!$F$12*CostSold!I4
B13: =CostTotal!B16 | C13: =CostTotal!$D$16+CostTotal!$F$16*C4 | D13: =CostTotal!$D$16+CostTotal!$F$16*D4 | E13: =CostTotal!$D$16+CostTotal!$F$16*E4 | F13: =CostTotal!$D$16+CostTotal!$F$16*F4 | G13: =CostTotal!$D$16+CostTotal!$F$16*G4 | H13: =CostTotal!$D$16+CostTotal!$F$16*H4 | I13: =CostTotal!$D$16+CostTotal!$F$16*I4
B14: =CostTotal!B14 | C14: =CostTotal!$D$14+CostTotal!$F$14*C4 | D14: =CostTotal!$D$14+CostTotal!$F$14*D4 | E14: =CostTotal!$D$14+CostTotal!$F$14*E4 | F14: =CostTotal!$D$14+CostTotal!$F$14*F4 | G14: =CostTotal!$D$14+CostTotal!$F$14*G4 | H14: =CostTotal!$D$14+CostTotal!$F$14*H4 | I14: =CostTotal!$D$14+CostTotal!$F$14*I4
B15: Marketing xarajatlar | C15: =CostTotal!$D$15+CostTotal!$F$15*C4 | D15: =CostTotal!$D$15+CostTotal!$F$15*D4 | E15: =CostTotal!$D$15+CostTotal!$F$15*E4 | F15: =CostTotal!$D$15+CostTotal!$F$15*F4 | G15: =CostTotal!$D$15+CostTotal!$F$15*G4 | H15: =CostTotal!$D$15+CostTotal!$F$15*H4 | I15: =CostTotal!$D$15+CostTotal!$F$15*I4
B16: =CostTotal!B13 | C16: =CostTotal!$D$13+CostTotal!$F$13*C4 | D16: =CostTotal!$D$13+CostTotal!$F$13*D4 | E16: =CostTotal!$D$13+CostTotal!$F$13*E4 | F16: =CostTotal!$D$13+CostTotal!$F$13*F4 | G16: =CostTotal!$D$13+CostTotal!$F$13*G4 | H16: =CostTotal!$D$13+CostTotal!$F$13*H4 | I16: =CostTotal!$D$13+CostTotal!$F$13*I4
B17: Davr xarajatlari | C17: =SUM(C11:C16) | D17: =SUM(D11:D16) | E17: =SUM(E11:E16) | F17: =SUM(F11:F16) | G17: =SUM(G11:G16) | H17: =SUM(H11:H16) | I17: =SUM(I11:I16)
B18: Operatsion xarajatlar | C18: =+C10+C17 | D18: =+D10+D17 | E18: =+E10+E17 | F18: =+F10+F17 | G18: =+G10+G17 | H18: =+H10+H17 | I18: =+I10+I17
B19: Kredit foizlari | C19: =SUM(Loans!E12:E23) | D19: =SUM(Loans!E24:E35) | E19: =SUM(Loans!E36:E47) | F19: =SUM(Loans!E48:E59) | G19: =SUM(Loans!E60:E72) | H19: =SUM(Loans!E72:E83) | I19: =SUM(Loans!E84:E95)
B20: Jami moliyaviy xarajatlar | C20: =SUM(C19:C19) | D20: =SUM(Loans!E24:E35) | E20: =SUM(E19) | F20: =SUM(F19) | G20: =SUM(G19) | H20: =SUM(Loans!E72:E83) | I20: =SUM(Loans!E84:E95)
B21: SOTILGAN MAHSULOTLARNING XARAJATLARI | C21: =C18+C20 | D21: =D18+D20 | E21: =E18+E20 | F21: =F18+F20 | G21: =G18+G20 | H21: =H18+H20 | I21: =I18+I20

Sheet ProfLoss
B2: KUTILAYOTGAN FOYDA VA ZARAR | G2: 12-ILOVA
B3: Ko'rsatgichlar | C3: =ProdPlan!C23 | D3: =ProdPlan!D23 | E3: =ProdPlan!E23 | F3: =ProdPlan!F23 | G3: =+ProdPlan!G23 | H3: =+ProdPlan!H23 | I3: =ProdPlan!I23
B4: Sotishdan tushgan daromad | C4: 1260000000 | D4: 1350000000 | E4: 1440000000 | F4: 1530000000 | G4: 1620000000 | H4: 1710000000 | I4: 1800000000
B5: Налог на потребление ГСМ | C5: =Taxes!E5 | D5: =Taxes!F5 | E5: =Taxes!G5 | F5: =Taxes!H5
B6: Sof sotishdan tushgan daromad | C6: 1260000000 | D6: 1350000000 | E6: 1440000000 | F6: 1530000000 | G6: 1620000000 | H6: 1710000000 | I6: 1800000000
B7: xizmatlar | C7: 928080000 | D7: 958080000 | E7: 988080000 | F7: 1018080000 | G7: 1048080000 | H7: 1078080000 | I7: 1083080000
B8: Umumiy daromad | C8: 331920000 | D8: 391920000 | E8: 451920000 | F8: 511920000 | G8: 571920000 | H8: 631920000 | I8: 716920000
B9: Ma'muriy xarajatlar | C9: =CostSold!C11+CostSold!C12 | D9: =CostSold!D11+CostSold!D12 | E9: =CostSold!E11+CostSold!E12 | F9: =CostSold!F11+CostSold!F12 | G9: =CostSold!G11+CostSold!G12 | H9: =CostSold!H11+CostSold!H12 | I9: =CostSold!I11+CostSold!I12
B10: Marketing xarajatlar | C10: =CostSold!C15 | D10: =CostSold!D15 | E10: =CostSold!E15 | F10: =CostSold!F15 | G10: =CostSold!G15 | H10: =CostSold!H15 | I10: =CostSold!I15
B11: Boshqa xarajatlar | C11: =+CostSold!C13+CostSold!C14+CostSold!C16 | D11: =+CostSold!D13+CostSold!D14+CostSold!D16 | E11: =+CostSold!E13+CostSold!E14+CostSold!E16 | F11: =+CostSold!F13+CostSold!F14+CostSold!F16 | G11: =+CostSold!G13+CostSold!G14+CostSold!G16 | H11: =+CostSold!H13+CostSold!H14+CostSold!H16 | I11: =+CostSold!I13+CostSold!I14+CostSold!I16
B12: Operatsion foyda | C12: 170220000 | D12: 223470000 | E12: 276720000 | F12: 329970000 | G12: 383220000 | H12: 436470000 | I12: 514720000
B13: Moliyaviy xarajatlar | C13: 48506687 | D13: 44217073 | E13: 38529014 | F13: 31991488 | G13: 24477635 | H13: 15841649 | I13: 5915945.9
B14: Soliq to'laguncha foyda | C14: 1.2171331e+08 | D14: 1.7925293e+08 | E14: 2.3819099e+08 | F14: 2.9797851e+08 | G14: 3.5874236e+08 | H14: 4.2062835e+08 | I14: 5.0880405e+08
B15: soliqlar | C15: 50400000 | D15: 54000000 | E15: 57600000 | F15: 61200000 | G15: 64800000 | H15: 68400000 | I15: 72000000
B16: Прочие налоги и отчисления | C16: =Taxes!E16 | D16: =Taxes!F16 | E16: =Taxes!G16 | F16: =Taxes!H16
B17: Sof daromad | C17: 71313313 | D17: 1.2525293e+08 | E17: 1.8059099e+08 | F17: 2.3677851e+08 | G17: 2.9394236e+08 | H17: 3.5222835e+08 | I17: 4.3680405e+08
B18: Rentabillik ko'rsatgichlari
B19: Sof rentabillik | C19: =C17/C6 | D19: =D17/D6 | E19: =E17/E6 | F19: =F17/F6 | G19: =G17/G6 | H19: =H17/H6 | I19: =I17/I6
B20: Yalpi rentabillik | C20: =C8/C6 | D20: =D8/D6 | E20: =E8/E6 | F20: =F8/F6 | G20: =G8/G6 | H20: =H8/H6 | I20: =I8/I6

Sheet CashFlow
B2: PUL OQIMI | H2: 13-ILOVA
B3: Ko'rsatgichlar | C3: 0 год | D3: =ProdPlan!C23 | E3: =ProdPlan!D23 | F3: =ProdPlan!E23 | G3: =ProdPlan!F23 | H3: =ProdPlan!G23 | I3: =ProdPlan!H23 | J3: =ProdPlan!I23
B4: Sotishdan tushgan tushum | C4: 0 | D4: 1260000000 | E4: 1350000000 | F4: 1440000000 | G4: 1530000000 | H4: 1620000000 | I4: 1710000000 | J4: 1800000000
B5: =ProfLoss!B5 | C5: =(C4*120%)/20% | D5: =ProfLoss!C5 | E5: =ProfLoss!D5 | F5: =ProfLoss!E5 | G5: =ProfLoss!F5
B7: Sotishdan tushgan naqd pul | C7: =C4-C6 | D7: 1260000000 | E7: 1350000000 | F7: 1440000000 | G7: 1530000000 | H7: 1620000000 | I7: 1710000000 | J7: 1800000000
B8: Xizmatning bevosita xarajatlari | C8: 0 | D8: 928080000 | E8: 958080000 | F8: 988080000 | G8: 1018080000 | H8: 1048080000 | I8: 1078080000 | J8: 1083080000
B9: Yalpi pul tushumi | C9: =C7-C8 | D9: 331920000 | E9: 391920000 | F9: 451920000 | G9: 511920000 | H9: 571920000 | I9: 631920000 | J9: 716920000
B10: Amortizatsiya | C10: 0 | D10: =Depreciate!E7 | E10: =Depreciate!F7 | F10: =Depreciate!G7 | G10: =Depreciate!H7 | H10: =Depreciate!I7 | I10: =Depreciate!J7 | J10: =Depreciate!K7
B11: Marketing xarajatlar | C11: 0 | D11: =CostSold!C15 | E11: =CostSold!D15 | F11: =CostSold!E15 | G11: =CostSold!F15 | H11: =CostSold!G15 | I11: =CostSold!H15 | J11: =CostSold!I15
B12: Ma'muriy xarajatlar | C12: 0 | D12: =CostSold!C11+CostSold!C12 | E12: =CostSold!D11+CostSold!D12 | F12: =CostSold!E11+CostSold!E12 | G12: =CostSold!F11+CostSold!F12 | H12: =CostSold!G11+CostSold!G12 | I12: =CostSold!H11+CostSold!H12 | J12: =CostSold!I11+CostSold!I12
B13: Boshqa xarajatlar | C13: 0 | D13: =ProfLoss!C11 | E13: =ProfLoss!D11 | F13: =ProfLoss!E11 | G13: =ProfLoss!F11 | H13: =ProfLoss!G11 | I13: =ProfLoss!H11 | J13: =ProfLoss!I11
B14: Operatsion pul oqimi | C14: =C9+C10-C11-C12-C13 | D14: 245220000 | E14: 298470000 | F14: 351720000 | G14: 404970000 | H14: 458220000 | I14: 511470000 | J14: 589720000
B15: Собственные средства | C15: -500000000 | D15: 0
B16: Инвестиции в основной капитал | C16: ='Share of Costs'!G6
B17: Финансовые издержки | C17: ='Share of Costs'!C10
B18: Foiz to'lovlari | D18: 48506687 | E18: 44217073 | F18: 38529014 | G18: 31991488 | H18: 24477635 | I18: 15841649 | J18: 5915945.9
B19: Soliqlar | C19: 0 | D19: 50400000 | E19: 54000000 | F19: 57600000 | G19: 61200000 | H19: 64800000 | I19: 68400000 | J19: 72000000
B20: Sof pul oqimi | C20: =C14+C15-C16-C17-C18-C19 | D20: =D14+D15-D16-D17-D18-D19 | E20: =E14-E15-E16-E17-E18-E19 | F20: =F14-F15-F16-F17-F18-F19 | G20: =G14-G15-G16-G17-G18-G19 | H20: =H14-H15-H16-H17-H18-H19 | I20: =I14-I15-I16-I17-I18-I19 | J20: =J14-J15-J16-J17-J18-J19
B22: Asosiy qarz to'lovi | D22: =SUM(Loans!C12:C23) | E22: =SUM(Loans!C24:C35) | F22: =SUM(Loans!C36:C47) | G22: =SUM(Loans!C48:C59) | H22: =SUM(Loans!C60:C71) | I22: =SUM(Loans!C72:C83) | J22: =SUM(Loans!C84:C95)
B23: Kredit to'langanidan keyin naqd pul | C23: =C20-C22 | D23: =D20-D22 | E23: =E20-E22 | F23: =F20-F22 | G23: =G20-G22 | H23: =H20-H22 | I23: =I20-I22 | J23: =J20-J22
B24: Moliyaviy so'rovlar | C24: =-C23
B25: Поток наличности | C25: =C23+C24 | D25: =D23-D24 | E25: =E23-E24 | F25: =F23-F24 | G25: =G23-G24
B26: Kumulyatuv pul oqimi | C26: =C25 | D26: =D23+C26 | E26: =E23+D26 | F26: =F23+E26 | G26: =G23+F26 | H26: =H23+G26 | I26: =I23+H26 | J26: =J23+I26
B27: Xizmat ko'rsatish omili. Qarz | D27: - | E27: - | F27: =(F14-F19)/(F18+F22) | G27: =(G14-G19)/(G18+G22) | H27: =(H14-H19)/(H18+H22) | I27: =(I14-I19)/(I18+I22) | J27: =(J14-J19)/(J18+J22)

Sheet npv
E3: 14-ILOVA
B4: Sof joriy qiymatni hisoblash
B5: YIL | C5: Sof pul oqimi | D5: 13,5% qayta moliyalash stavkasi bo'yicha chegirma koeffitsienti (o'rtacha tortilgan stavka) | E5: Pul oqimining joriy qiymati
B6: Investitsion xarajatlar | C6: -500000000
B7: 1-yil | C7: 1.2916773e+08 | D7: 0.88105727 | E7: 1.1380417e+08
B8: 2-yil | C8: 1.6216546e+08 | D8: 0.77626191 | E8: 1.2588287e+08
B9: 3-yil | C9: 2.1181546e+08 | D9: 0.6839312 | E9: 1.448672e+08
B10: 4-yil | C10: 2.6146546e+08 | D10: 0.60258255 | E10: 1.5755453e+08
B11: 5-yil | C11: 3.1111546e+08 | D11: 0.53090974 | E11: 1.6517423e+08
B12: 6-yil | C12: 3.6076546e+08 | D12: 0.46776188 | E12: 1.6875233e+08
B13: 7-yil | C13: 4.3541546e+08 | D13: 0.41212501 | E13: 1.794456e+08
C14: Jami joriy qiymat | D14: JJQ | E14: =SUM(E7:E11)
C15: Investitsion xarajatlar | D15: IX | E15: =C6
C16: Sof joriy qiymatni hisoblash (SJQ=JJQ-IX) | D16: SJQ | E16: 5.5548093e+08
C17: Investitsiyalar rentabelligi indeksini hisoblash IR=SJQ/IX+1 | D17: IR | E17: =E16/E15+1
C18: Ichki daromad darajasi | D18: IDD | E18: 37.34
C19: Investitsiyalarni qaytarish muddati diskontlangan pul oqimi loyihasi | D19: IQM | E19: =[2]Loans!D3
